Workbook

Sheet tong_hop
A1: Tổng hợp error_audit (tự tính lại khi sửa nhãn ở sheet error_audit)
A3: Loại lỗi | B3: ViVQA (n) | C3: ViVQA (%) | D3: ViTextVQA (n) | E3: ViTextVQA (%) | F3: Tổng (n) | G3: Tổng (%)
A4: Định dạng / độ dài (ý đúng) | B4: =COUNTIFS(error_audit!$L$2:$L$201,A4,error_audit!$B$2:$B$201,"vivqa") | C4: =B4/COUNTIF(error_audit!$B$2:$B$201,"vivqa") | D4: =COUNTIFS(error_audit!$L$2:$L$201,A4,error_audit!$B$2:$B$201,"vitextvqa") | E4: =D4/COUNTIF(error_audit!$B$2:$B$201,"vitextvqa") | F4: =COUNTIF(error_audit!$L$2:$L$201,A4) | G4: =F4/200
A5: Đồng nghĩa / khác từ (ý đúng) | B5: =COUNTIFS(error_audit!$L$2:$L$201,A5,error_audit!$B$2:$B$201,"vivqa") | C5: =B5/COUNTIF(error_audit!$B$2:$B$201,"vivqa") | D5: =COUNTIFS(error_audit!$L$2:$L$201,A5,error_audit!$B$2:$B$201,"vitextvqa") | E5: =D5/COUNTIF(error_audit!$B$2:$B$201,"vitextvqa") | F5: =COUNTIF(error_audit!$L$2:$L$201,A5) | G5: =F5/200
A6: Đọc chữ sai (OCR) | B6: =COUNTIFS(error_audit!$L$2:$L$201,A6,error_audit!$B$2:$B$201,"vivqa") | C6: =B6/COUNTIF(error_audit!$B$2:$B$201,"vivqa") | D6: =COUNTIFS(error_audit!$L$2:$L$201,A6,error_audit!$B$2:$B$201,"vitextvqa") | E6: =D6/COUNTIF(error_audit!$B$2:$B$201,"vitextvqa") | F6: =COUNTIF(error_audit!$L$2:$L$201,A6) | G6: =F6/200
A7: Sai dấu thanh | B7: =COUNTIFS(error_audit!$L$2:$L$201,A7,error_audit!$B$2:$B$201,"vivqa") | C7: =B7/COUNTIF(error_audit!$B$2:$B$201,"vivqa") | D7: =COUNTIFS(error_audit!$L$2:$L$201,A7,error_audit!$B$2:$B$201,"vitextvqa") | E7: =D7/COUNTIF(error_audit!$B$2:$B$201,"vitextvqa") | F7: =COUNTIF(error_audit!$L$2:$L$201,A7) | G7: =F7/200
A8: Sai vùng / không có trong ảnh (hallucination) | B8: =COUNTIFS(error_audit!$L$2:$L$201,A8,error_audit!$B$2:$B$201,"vivqa") | C8: =B8/COUNTIF(error_audit!$B$2:$B$201,"vivqa") | D8: =COUNTIFS(error_audit!$L$2:$L$201,A8,error_audit!$B$2:$B$201,"vitextvqa") | E8: =D8/COUNTIF(error_audit!$B$2:$B$201,"vitextvqa") | F8: =COUNTIF(error_audit!$L$2:$L$201,A8) | G8: =F8/200
A9: Code-switching (tiếng Anh) | B9: =COUNTIFS(error_audit!$L$2:$L$201,A9,error_audit!$B$2:$B$201,"vivqa") | C9: =B9/COUNTIF(error_audit!$B$2:$B$201,"vivqa") | D9: =COUNTIFS(error_audit!$L$2:$L$201,A9,error_audit!$B$2:$B$201,"vitextvqa") | E9: =D9/COUNTIF(error_audit!$B$2:$B$201,"vitextvqa") | F9: =COUNTIF(error_audit!$L$2:$L$201,A9) | G9: =F9/200
A10: Đếm sai | B10: =COUNTIFS(error_audit!$L$2:$L$201,A10,error_audit!$B$2:$B$201,"vivqa") | C10: =B10/COUNTIF(error_audit!$B$2:$B$201,"vivqa") | D10: =COUNTIFS(error_audit!$L$2:$L$201,A10,error_audit!$B$2:$B$201,"vitextvqa") | E10: =D10/COUNTIF(error_audit!$B$2:$B$201,"vitextvqa") | F10: =COUNTIF(error_audit!$L$2:$L$201,A10) | G10: =F10/200
A11: Gold sai / nhiễu | B11: =COUNTIFS(error_audit!$L$2:$L$201,A11,error_audit!$B$2:$B$201,"vivqa") | C11: =B11/COUNTIF(error_audit!$B$2:$B$201,"vivqa") | D11: =COUNTIFS(error_audit!$L$2:$L$201,A11,error_audit!$B$2:$B$201,"vitextvqa") | E11: =D11/COUNTIF(error_audit!$B$2:$B$201,"vitextvqa") | F11: =COUNTIF(error_audit!$L$2:$L$201,A11) | G11: =F11/200
A12: Khác | B12: =COUNTIFS(error_audit!$L$2:$L$201,A12,error_audit!$B$2:$B$201,"vivqa") | C12: =B12/COUNTIF(error_audit!$B$2:$B$201,"vivqa") | D12: =COUNTIFS(error_audit!$L$2:$L$201,A12,error_audit!$B$2:$B$201,"vitextvqa") | E12: =D12/COUNTIF(error_audit!$B$2:$B$201,"vitextvqa") | F12: =COUNTIF(error_audit!$L$2:$L$201,A12) | G12: =F12/200
A13: B2 đúng ý (b2_dung_nghia = Có) | B13: =COUNTIFS(error_audit!$M$2:$M$201,"Có",error_audit!$B$2:$B$201,"vivqa") | C13: =B13/COUNTIF(error_audit!$B$2:$B$201,"vivqa") | D13: =COUNTIFS(error_audit!$M$2:$M$201,"Có",error_audit!$B$2:$B$201,"vitextvqa") | E13: =D13/COUNTIF(error_audit!$B$2:$B$201,"vitextvqa") | F13: =COUNTIF(error_audit!$M$2:$M$201,"Có") | G13: =F13/200
A14: Hallucination = Có | B14: =COUNTIFS(error_audit!$N$2:$N$201,"Có",error_audit!$B$2:$B$201,"vivqa") | C14: =B14/COUNTIF(error_audit!$B$2:$B$201,"vivqa") | D14: =COUNTIFS(error_audit!$N$2:$N$201,"Có",error_audit!$B$2:$B$201,"vitextvqa") | E14: =D14/COUNTIF(error_audit!$B$2:$B$201,"vitextvqa") | F14: =COUNTIF(error_audit!$N$2:$N$201,"Có") | G14: =F14/200
A15: Cần xem lại (X) | B15: =COUNTIFS(error_audit!$R$2:$R$201,"X",error_audit!$B$2:$B$201,"vivqa") | C15: =B15/COUNTIF(error_audit!$B$2:$B$201,"vivqa") | D15: =COUNTIFS(error_audit!$R$2:$R$201,"X",error_audit!$B$2:$B$201,"vitextvqa") | E15: =D15/COUNTIF(error_audit!$B$2:$B$201,"vitextvqa") | F15: =COUNTIF(error_audit!$R$2:$R$201,"X") | G15: =F15/200
A17: Ghi chú: mẫu = 200 câu B2 trả lời SAI theo EM (100 ViVQA + 100 ViTextVQA). Tỉ lệ là tỉ lệ TRONG MẪU LỖI, không phải trên toàn bộ test.
A18: Quy trình: Claude gán nhãn sơ bộ (AI-assisted pre-annotation) → Hoàng duyệt cả 200 dòng (human-verified). Số cuối dùng sau khi duyệt.

Sheet huong_dan
A1: Mục đích | B1: Duyệt tay 400 mẫu để (1) đo nhiễu nhãn của dataset, (2) phân loại lỗi của B2 cho error/hallucination analysis.
A2: Cách làm | B2: Mở ảnh bằng link ở cột 'anh' (hoặc tìm theo tên file trong thư mục images/). Chọn nhãn ở các cột màu vàng bằng dropdown; ghi chú nếu cần.
A3: data_audit | B3: Mẫu TRAIN. 'nhan_goc' = nhãn gốc đúng/sai/mơ hồ so với ảnh; 'loai_van_de' theo danh sách; nếu sai ghi đáp án đúng.
A4: error_audit | B4: Câu TEST B2 sai EM. 'loai_loi' = nguyên nhân chính (1 nhãn); 'b2_dung_nghia' = Có nếu người đọc chấp nhận câu trả lời của B2; 'hallucination' = Có nếu B2 nói thứ KHÔNG có trong ảnh.
A5: Nhãn data_audit | B5: OK | Dịch sai / dịch máy (vd 'tía') | Sai dấu thanh / chính tả | Đáp án không khớp ảnh | Câu hỏi mơ hồ / nhiều đáp án đúng | Đáp án không chuẩn hoá (dài, thừa chữ) | Khác
A6: Nhãn error_audit | B6: Định dạng / độ dài (ý đúng) | Đồng nghĩa / khác từ (ý đúng) | Đọc chữ sai (OCR) | Sai dấu thanh | Sai vùng / không có trong ảnh (hallucination) | Code-switching (tiếng Anh) | Đếm sai | Gold sai / nhiễu | Khác
A7: Phân công gợi ý | B7: SV2 (Dataset/OCR): data_audit. SV4 (Evaluation) + Hoàng: error_audit. ≈30 giây/dòng -> ≈1,5–2 giờ/200 dòng.
A8: Quy tắc | B8: Không sửa các cột không tô vàng. Mỗi người điền tên ở cột 'nguoi_duyet'. Dòng khó: chọn 'Khác' + ghi chú, không đoán.
A9: Chọn mẫu | B9: Tất định, seed 42: data_audit ViVQA 25 mẫu/loại câu hỏi (color, location, number, object), ViTextVQA 100 mẫu ngẫu nhiên; error_audit 100 câu B2 sai EM mỗi dataset.

Sheet data_audit
A1: stt | B1: dataset | C1: question_id | D1: question_type | E1: anh | F1: question | G1: answers | H1: nhan_goc | I1: loai_van_de | J1: dap_an_dung_neu_sai | K1: ghi_chu | L1: nguoi_duyet
A2: 1 | B2: vivqa | C2: train_2151 | D2: color | E2: COCO_train2014_000000214022.jpg | F2: màu sắc của những con chim là gì | G2: màu xanh lá
A3: 2 | B3: vivqa | C3: train_458 | D3: color | E3: COCO_train2014_000000272040.jpg | F3: màu của chiếc xe là gì | G3: màu xám
A4: 3 | B4: vivqa | C4: train_5352 | D4: color | E4: COCO_train2014_000000181104.jpg | F4: màu của tường là gì | G4: màu đen
A5: 4 | B5: vivqa | C5: train_4775 | D5: color | E5: COCO_train2014_000000378832.jpg | F5: màu của con mèo là gì | G5: màu cam
A6: 5 | B6: vivqa | C6: train_4337 | D6: color | E6: COCO_train2014_000000426470.jpg | F6: màu sắc của biển là gì | G6: màu xanh dương
A7: 6 | B7: vivqa | C7: train_2696 | D7: color | E7: COCO_train2014_000000285042.jpg | F7: màu của cưỡi là gì | G7: màu xanh lá
A8: 7 | B8: vivqa | C8: train_2019 | D8: color | E8: COCO_train2014_000000213536.jpg | F8: màu của bầu trời là gì | G8: màu xám
A9: 8 | B9: vivqa | C9: train_10785 | D9: color | E9: COCO_train2014_000000385844.jpg | F9: màu của nhà vệ sinh là gì | G9: màu xanh lá
A10: 9 | B10: vivqa | C10: train_1706 | D10: color | E10: COCO_train2014_000000539675.jpg | F10: màu của tường là gì | G10: màu xám
A11: 10 | B11: vivqa | C11: train_8289 | D11: color | E11: COCO_train2014_000000394483.jpg | F11: màu của áo là gì | G11: màu xanh dương
A12: 11 | B12: vivqa | C12: train_578 | D12: color | E12: COCO_train2014_000000176249.jpg | F12: màu của vòi nước là gì | G12: màu vàng
A13: 12 | B13: vivqa | C13: train_561 | D13: color | E13: COCO_train2014_000000324663.jpg | F13: màu của cánh buồm là gì | G13: màu vàng
... A201: 200 | B201: vitextvqa | C201: train_14431 | D201: unknown | E201: 4825.jpg | F201: bảng quảng cáo được làm với giá như thế nào ? | G201: giá rẻ

Sheet error_audit
A1: stt | B1: dataset | C1: question_id | D1: question_type | E1: anh | F1: question | G1: gold | H1: B1 | I1: B2 | J1: R1 | K1: ANLS_B2 | L1: loai_loi | M1: b2_dung_nghia | N1: hallucination | O1: ghi_chu | P1: nguoi_duyet | Q1: ly_do_claude | R1: can_xem_lai | S1: nhan_cu_cua_Hoang (dong 1-10)
A2: 1 | B2: vivqa | C2: test_638 | D2: location | E2: COCO_train2014_000000142563.jpg | F2: người đàn ông cưỡi một con ngựa ở đâu | G2: chuồng | H2: trang trại | I2: sân vận động | K2: 0 | L2: Khác | M2: Không | N2: Không | O2: sân vận động khác với trang trại và chuồng | Q2: Đấu trường rodeo có khán đài; 'sân vận động' gần nhưng khác gold 'chuồng' (corral). Không bịa vật thể. | S2: ĐÃ SỬA — hallucination: 'Có' → 'Không'
A3: 2 | B3: vivqa | C3: test_1277 | D3: location | E3: COCO_val2014_000000161470.jpg | F3: chim bắn nước tung tóe ở đâu | G3: bồn tắm | H3: trên bể nước | I3: bồn | K3: 0 | L3: Định dạng / độ dài (ý đúng) | M3: Có | N3: Không | Q3: Bồn tắm chim; B2 thiếu chữ 'tắm'. | S3: Giữ nguyên
A4: 3 | B4: vivqa | C4: test_1061 | D4: location | E4: COCO_train2014_000000237762.jpg | F4: một số xoài và chuối được đặt ở đâu | G4: đĩa ăn | H4: trên đĩa | I4: bát | K4: 0 | L4: Đồng nghĩa / khác từ (ý đúng) | M4: Có | N4: Không | Q4: Đĩa vuông sâu lòng, gọi 'bát' chấp nhận được. | S4: Giữ nguyên
A5: 4 | B5: vivqa | C5: test_942 | D5: location | E5: COCO_train2014_000000287998.jpg | F5: những trái cam được đặt ở đâu | G5: cái rổ | H5: trên bát hứng | I5: chậu | K5: 0 | L5: Khác | M5: Không | N5: Không | Q5: Cam trong rổ inox (colander) đặt trong bồn rửa; 'chậu' sai vật chứa. | S5: ĐÃ SỬA — loai_loi: 'Đồng nghĩa / khác từ (ý đúng)' → 'Khác'; b2_dung_nghia: 'Có' → 'Không'
A6: 5 | B6: vivqa | C6: test_1807 | D6: object | E6: COCO_val2014_000000558633.jpg | F6: nhóm ăn gì ở bàn có đĩa màu đỏ và trắng | G6: bữa ăn tối | H6: bánh mì | I6: bữa ăn | K6: 0.6 | L6: Định dạng / độ dài (ý đúng) | M6: Có | N6: Không | Q6: Thiếu chữ 'tối'. | S6: Giữ nguyên
A7: 6 | B7: vivqa | C7: test_1687 | D7: object | E7: COCO_val2014_000000477010.jpg | F7: người đàn ông giao những gì theo dõi khán giả | G7: quả bóng | H7: đánh tennis | I7: vợt | K7: 0 | L7: Khác | M7: Không | N7: Không | O7: gold là quả bóng nó khác với vợt | Q7: Câu hỏi dịch máy ('serve' -> 'giao'); đáp án là quả bóng, B2 nêu cây vợt có trong ảnh. | S7: ĐÃ SỬA — hallucination: 'Có' → 'Không'
A8: 7 | B8: vivqa | C8: test_1622 | D8: object | E8: COCO_val2014_000000399274.jpg | F8: những gì chuyến tàu di chuyển nhanh chóng, mọi thứ xung quanh mờ nhạt | G8: đường sắt | H8: Đường sắt. | I8: tàu hỏa | K8: 0 | L8: Khác | M8: Không | N8: Không | O8: câu trả lời là đường sắt nhưng B2 lại trả lời là tàu hỏa | Q8: Câu hỏi dịch máy khó hiểu; tàu hỏa có trong ảnh. B1 đúng, B2 sai. | S8: ĐÃ SỬA — hallucination: 'Có' → 'Không'
A9: 8 | B9: vivqa | C9: test_1372 | D9: object | E9: COCO_val2014_000000437789.jpg | F9: cái gì cùng với cam, cà rốt, bông cải xanh và các loại thực phẩm khác | G9: quả táo | H9: hạt dẻ | I9: táo | K9: 0 | L9: Định dạng / độ dài (ý đúng) | M9: Có | N9: Không | Q9: Thiếu chữ 'quả'. | S9: ĐÃ SỬA — b2_dung_nghia: 'Không' → 'Có'
A10: 9 | B10: vivqa | C10: test_926 | D10: location | E10: COCO_train2014_000000122937.jpg | F10: em bé đang ngồi ở đâu | G10: găng tay | H10: trên găng tay baseball | I10: giường | K10: 0 | L10: Sai vùng / không có trong ảnh (hallucination) | M10: Không | N10: Có | O10: gold là găng tay nhưng b2 là trên giường | Q10: Em bé nằm trong găng tay bóng chày; không có giường. B1 đúng ý. | S10: ĐÃ SỬA — loai_loi: 'Khác' → 'Sai vùng / không có trong ảnh (hallucination)'
A11: 10 | B11: vivqa | C11: test_1260 | D11: location | E11: COCO_train2014_000000277746.jpg | F11: người phụ nữ đang đứng ở đâu khi uống đồ uống | G11: nhà vệ sinh | H11: bathroom | I11: phòng tắm | K11: 0 | L11: Đồng nghĩa / khác từ (ý đúng) | M11: Có | N11: Không | Q11: Nhà vệ sinh công cộng; 'phòng tắm' đồng nghĩa. | S11: Giữ nguyên
A12: 11 | B12: vivqa | C12: test_726 | D12: location | E12: COCO_train2014_000000013922.jpg | F12: chuối và các thành phần khác ở đâu | G12: cái nồi | H12: trên đĩa | I12: bát | K12: 0 | L12: Đồng nghĩa / khác từ (ý đúng) | M12: Có | N12: Không | Q12: Vật chứa mơ hồ (cối máy xay/nồi/bát); 'bát' chấp nhận được.
A13: 12 | B13: vivqa | C13: test_935 | D13: location | E13: COCO_train2014_000000154547.jpg | F13: nơi để đồ cho trẻ mới biết đi và đeo ván trượt, mỉm cười trước ống kính ở đâu | G13: trượt tuyết | H13: trong rừng | I13: đường bộ | K13: 0 | L13: Khác | M13: Không | N13: Không | Q13: Câu hỏi dịch máy khó hiểu; bé trượt tuyết trên đường tuyết.
A14: 13 | B14: vivqa | C14: test_2844 | D14: number | E14: COCO_val2014_000000117222.jpg | F14: có bao nhiêu người đàn ông đi xe đạp với một đống chuối lớn | G14: hai | H14: 2 | I14: ba | K14: 0 | L14: Đếm sai | M14: Không | N14: Không | Q14: 1 người đạp xe chở chuối + 2 người đi xe máy; B2 đếm cả 3.
A15: 14 | B15: vivqa | C15: test_1225 | D15: location | E15: COCO_train2014_000000036341.jpg | F15: đứa trẻ đang tập đánh bóng ở đâu | G15: lồng | H15: Trường học. | I15: chuồng | K15: 0.5 | L15: Khác | M15: Không | N15: Không | Q15: Lồng tập đánh bóng (batting cage); 'chuồng' sai từ.
A16: 15 | B16: vivqa | C16: test_359 | D16: color | E16: COCO_train2014_000000301943.jpg | F16: màu của con chó là gì | G16: màu nâu | H16: Đen, trắng, và vàng. | I16: màu trắng | K16: 0 | L16: Gold sai / nhiễu | M16: Có | N16: Không | Q16: Chó trắng-đen có vệt nâu; gold chỉ 1 màu (nhiễu N1), 'trắng' cũng hợp lý.
A17: 16 | B17: vivqa | C17: test_2370 | D17: object | E17: COCO_val2014_000000462006.jpg | F17: người phụ nữ cầm một em bé đang ăn gì | G17: cà rốt | H17: carrot | I17: hạt | K17: 0 | L17: Sai vùng / không có trong ảnh (hallucination) | M17: Không | N17: Có | Q17: Bé ăn cà rốt; không có 'hạt'. B1 'carrot' đúng ý nhưng tiếng Anh.
A18: 17 | B18: vivqa | C18: test_1079 | D18: location | E18: COCO_train2014_000000044240.jpg | F18: xe máy cổ điển đang đậu ở đâu | G18: đường phố | H18: Đường. | I18: sân | K18: 0 | L18: Gold sai / nhiễu | M18: Có | N18: Không | Q18: Xe máy đỗ cạnh bãi cỏ trước nhà; 'sân' hợp lý hơn gold 'đường phố'.
A19: 18 | B19: vivqa | C19: test_1072 | D19: location | E19: COCO_train2014_000000476993.jpg | F19: mặt phẳng trắng, cam và đỏ còn lại ở đâu | G19: sân bay | H19: trên máy bay | I19: hành lang | K19: 0 | L19: Sai vùng / không có trong ảnh (hallucination) | M19: Không | N19: Có | Q19: Máy bay trước nhà chứa máy bay; không có 'hành lang'.
A20: 19 | B20: vivqa | C20: test_1235 | D20: location | E20: COCO_train2014_000000036482.jpg | F20: người lính đang giữ một chiếc xe đạp màu xanh ở đâu | G20: văn phòng | H20: trong phòng | I20: phòng | K20: 0.556 | L20: Định dạng / độ dài (ý đúng) | M20: Có | N20: Không | Q20: Văn phòng; B2 'phòng' thiếu chữ.
A21: 20 | B21: vivqa | C21: test_1604 | D21: object | E21: COCO_val2014_000000335810.jpg | F21: những gì chứa đầy cam lát bên cạnh một đống chuối | G21: đĩa ăn | H21: cam lát | I21: bát | K21: 0 | L21: Khác | M21: Không | N21: Không | Q21: Cam lát trên đĩa; gọi nhầm vật chứa thành 'bát'.
A22: 21 | B22: vivqa | C22: test_165 | D22: color | E22: COCO_train2014_000000415222.jpg | F22: màu của quả táo là gì | G22: màu cam | H22: xanh lá cây | I22: màu xanh lá | K22: 0 | L22: Gold sai / nhiễu | M22: Có | N22: Không | Q22: Quả táo màu xanh lá; gold 'màu cam' là màu của quả cam bên cạnh (nhãn sai).
A23: 22 | B23: vivqa | C23: test_27 | D23: color | E23: COCO_train2014_000000087598.jpg | F23: màu của áo là gì | G23: màu đỏ | H23: Đỏ | I23: màu tía | K23: 0 | L23: Gold sai / nhiễu | M23: Có | N23: Không | Q23: Áo thun màu tím, áo phao màu đỏ; B2 đúng ý nhưng dùng 'tía' (học từ nhãn dịch máy).
... A101: 100 | B101: vivqa | C101: test_1612 | D101: object | E101: COCO_val2014_000000542325.jpg | F101: có gì đang ngồi trên một kệ trong lối vào của một ngôi nhà | G101: tượng đài | H101: đồ trang trí | I101: bức ảnh | K101: 0 | L101: Khác | M101: Không | N101: Không | Q101: Trên kệ là tượng; B2 'bức ảnh' (tranh treo tường có trong ảnh).
A102: 101 | B102: vitextvqa | C102: test_40032 | D102: unknown | E102: 13399.jpg | F102: trung tâm này đến từ đâu ? | G102: usatutoring | H102: Mỹ | I102: usa tutoring | J102: Trung tâm này đến từ Việt Nam. | K102: 0.917 | L102: Định dạng / độ dài (ý đúng) | M102: Có | N102: Không | Q102: Biển ghi 'USATutoring'; B2 đọc đúng, chỉ tách chữ khác gold.
A103: 102 | B103: vitextvqa | C103: test_15216 | D103: unknown | E103: 5073.jpg | F103: thời gian bức ảnh này được chụp là gì ? | G103: xuân canh tý 2020 | H103: 2020 | I103: 2020 | J103: Không thể xác định thời gian chụp ảnh từ bức ảnh này. | K103: 0 | L103: Định dạng / độ dài (ý đúng) | M103: Có | N103: Không | Q103: Banner 'Mừng Xuân Canh Tý 2020'; B2 chỉ trả '2020'.
A104: 103 | B104: vitextvqa | C104: test_11203 | D104: unknown | E104: 3771.jpg | F104: tuyên nguyễn là tên của cửa tiệm chuyên việc gì ? | G104: photocopy | H104: Tuyên Nguyễn là tên của cửa tiệm chuyên in ấn và dịch vụ liên quan như photo, coppy, làm card visit, danh thiếp | I104: photo - coppy | J104: Cửa tiệm chuyên in ấn và dịch vụ văn phòng. | K104: 0.818 | L104: Định dạng / độ dài (ý đúng) | M104: Có | N104: Không | Q104: Biển ghi 'PHOTO COPPY'; B2 chép đúng chữ trên biển, gold đã sửa chính tả.
A105: 104 | B105: vitextvqa | C105: test_44312 | D105: unknown | E105: 14790.jpg | F105: nhà xuất bản của cuốn sách này là ai ? | G105: nhà xuất bản thanh hóa | H105: Nhà xuất bản: Thiện Huệ. | I105: thanh hóa | J105: Nhà xuất bản của cuốn sách này là Thanh Hóa. | K105: 0 | L105: Định dạng / độ dài (ý đúng) | M105: Có | N105: Không | Q105: Thiếu 'nhà xuất bản'.
A106: 105 | B106: vitextvqa | C106: test_23522 | D106: unknown | E106: 7894.jpg | F106: nội dung bức hình là gì ? | G106: hoa kì phản đối hành vi gây hấn và khiêu khích của trung quốc | H106: Ngoại trưởng Mỹ Mike Pompeo nói rằng Trung Quốc phản đối hành vi gây hấn và khiêu khích của mình. | I106: hoa kỳ phản đối hành vi gây hấn và khiêu khích của trung quốc | J106: Bức hình là một trích dẫn từ một bài phát biểu của Ngoại trưởng Mỹ Mike Pompeo, nói về việc Trung Quốc gây hấn và khích | K106: 0.984 | L106: Gold sai / nhiễu | M106: Có | N106: Không | Q106: Ảnh ghi 'HOA KỲ'; B2 đúng, gold viết 'kì' (biến thể chính tả).
A107: 106 | B107: vitextvqa | C107: test_22027 | D107: unknown | E107: 7405.jpg | F107: số điện thoại liên lạc cho tiệm gia phú là gì ? | G107: 0702 200 670 - 0707 219 670 | H107: 0702 200 670, 0702 219 670 | I107: 0702 200 670 - 0702 219 670 | J107: 0702 200 670 - 0702 219 670 | K107: 0.96 | L107: Gold sai / nhiễu | M107: Có | N107: Không | Q107: Biển ghi 0702 200 670 - 0702 219 670; B2 đúng, gold sai số.
A108: 107 | B108: vitextvqa | C108: test_20815 | D108: unknown | E108: 6980.jpg | F108: chữ trên áo người mặc áo xanh dương là gì ? | G108: bemin | H108: GEMINI | I108: gome | J108: GOGO | K108: 0 | L108: Đọc chữ sai (OCR) | M108: Không | N108: Không | Q108: Áo khoác ghi 'BEMIN'; B2 đọc thành 'gome'.
A109: 108 | B109: vitextvqa | C109: test_16369 | D109: unknown | E109: 5461.jpg | F109: dàn sản phẩm trong ảnh là gì ? | G109: táo & kiwi new zealand | H109: Táo & Kiwi New Zealand | I109: táo & kiwi | J109: Dàn sản phẩm trong ảnh là các loại trái cây, cụ thể là táo và kiwi từ New Zealand. | K109: 0 | L109: Định dạng / độ dài (ý đúng) | M109: Có | N109: Không | Q109: Thiếu 'new zealand'.
A110: 109 | B110: vitextvqa | C110: test_43827 | D110: unknown | E110: 14622.jpg | F110: cửa hàng có bán món an gì về thịt nướng ? | G110: bún thịt nướng | H110: Bún thịt nướng | I110: bánh ướt | J110: Cửa hàng bán bún thịt nướng. | K110: 0 | L110: Sai vùng / không có trong ảnh (hallucination) | M110: Không | N110: Không | Q110: Biển có cả 'bún thịt nướng' và 'bánh ướt'; B2 đọc nhầm dòng (chữ có thật).
A111: 110 | B111: vitextvqa | C111: test_14748 | D111: unknown | E111: 4928.jpg | F111: thiên hương là cửa hàng gì ? | G111: đại lý mè xửng | H111: Thiên Hương là cửa hàng như Huê. | I111: như huệ | J111: Thiên Hương là cửa hàng nhu huế. | K111: 0 | L111: Sai vùng / không có trong ảnh (hallucination) | M111: Không | N111: Không | Q111: Biển: 'Đại lý mè xửng Thiên Hương — Cửa hàng Như Huệ'; B2 đọc nhầm vùng chữ.
A112: 111 | B112: vitextvqa | C112: test_41638 | D112: unknown | E112: 13923.jpg | F112: ted osius là ai ? | G112: cựu đại sứ quán mỹ tại việt nam | H112: Ted Osius là một cựu Đại sứ Mỹ tại Việt Nam. | I112: cựu đại sứ mỹ tại việt nam | J112: Ted Osius là Cự Đại sứ Mỹ tại Việt Nam. | K112: 0.839 | L112: Gold sai / nhiễu | M112: Có | N112: Không | Q112: Ảnh ghi 'Cựu Đại sứ Mỹ tại Việt Nam'; B2 đúng, gold thừa 'quán'.
A113: 112 | B113: vitextvqa | C113: test_44289 | D113: unknown | E113: 14783.jpg | F113: tên nội dung của bài báo ? | G113: sài gòn xưa | H113: Saigon Xưa | I113: saigon xưa | J113: "Saigon in ancient time" | K113: 0.727 | L113: Sai dấu thanh | M113: Có | N113: Không | Q113: Ảnh 'SÀIGÒN XƯA'; B2 viết 'saigon' (mất dấu, dính chữ).
... A121: 120 | B121: vitextvqa | C121: test_14358 | D121: unknown | E121: 4804.jpg | F121: trên áo màu xanh có chữ gì vậy ? | G121: đong tay tci | H121: DONG TAY TCi | I121: dong tay tcj | J121: DONG TAY TCI | K121: 0.833 | L121: Đọc chữ sai (OCR) | M121: Không | N121: Không | Q121: Áo ghi 'TCi'; B2 đọc thành 'tcj'.
A122: 121 | B122: vitextvqa | C122: test_20527 | D122: unknown | E122: 6882.jpg | F122: bên phải dòng người có bán gì ? | G122: coffee | H122: Đèn và hàng hóa. | I122: đồ nâu | J122: Bên phải dòng người có bán quần áo. | K122: 0 | L122: Sai vùng / không có trong ảnh (hallucination) | M122: Không | N122: Có | Q122: Gold là biển 'coffee'; không thấy chữ/vật 'đồ nâu' trong ảnh (không chắc chắn, cần xem lại). | R122: X
A123: 122 | B123: vitextvqa | C123: test_21326 | D123: unknown | E123: 7156.jpg | F123: trà sâm bí đao như thế nào ? | G123: thổi bay cơn nóng | H123: Trà sâm bí đao ngựa gia. | I123: ngọ gia | J123: Trà sâm bí đao là một loại trà được làm từ sâm và bí đao. | K123: 0 | L123: Sai vùng / không có trong ảnh (hallucination) | M123: Không | N123: Không | Q123: Câu hỏi về slogan 'thổi bay cơn nóng'; B2 đọc tên thương hiệu (và đọc sai) thay vì slogan.
A124: 123 | B124: vitextvqa | C124: test_34404 | D124: unknown | E124: 11430.jpg | F124: đây là nước nào ? | G124: nước cộng hòa xã hội chủ nghĩa việt nam | H124: Việt Nam | I124: cộng hòa xã hội chủ nghĩa việt nam | J124: Việt Nam | K124: 0.872 | L124: Định dạng / độ dài (ý đúng) | M124: Có | N124: Không | Q124: B2 thiếu chữ 'nước' ở đầu, đúng ý.
...
